Workbook

Sheet Read Me
A1: RV PARK UNDERWRITING — HOW TO USE
A3: WHAT THIS IS
A4: An RV-park deal-screening model built on the LindaAI underwriting framework. Drop in a
A5: deal's numbers and it tells you in minutes whether it makes money — using Linda's 5 key metrics, its 5
A6: quick hacks, NOI normalization, and its go / conditional / no-go rule. Works for RV parks and adapts
A7: directly to mobile home parks (same lot-rent math). Part of the LindaAI underwriting framework.
A9: LINDA'S 5 KEY METRICS (the heartbeat of the deal)
A10: 1. NOI — effective gross income (EGI) minus operating expenses. Every other metric flows from it.
A11: 2. Cap Rate = NOI / price. Higher = paying less. But a very high cap (14%+) usually means hidden risk.
A12: 3. DSCR = NOI / annual debt. Linda's floor is 1.35x — that's YOUR target, not just the lender's.
A13: 4. Net Profit = what's left after opex AND debt service.
A14: 5. Cash-on-Cash = net profit / cash invested. Linda's target is 10%+.
... A64: This is a screening tool, not investment advice. Verify every number and consult professionals.

Sheet Deal Summary
A1: DEAL SUMMARY
A2: =Underwriting!B3&" — "&Underwriting!B4
A4: THE ASSET
A5: Number of Sites | B5: =Underwriting!B8 | C5: Purchase Price | D5: =Underwriting!B9
A6: Price per Site | B6: =Underwriting!B9/Underwriting!B8 | C6: Year-1 NOI | D6: =Underwriting!B40
A8: FINANCING
A9: Loan Amount | B9: =Underwriting!B54 | C9: Down Payment (Equity) | D9: =Underwriting!B55
A10: Interest Rate | B10: =Underwriting!B45 | C10: Amortization (yrs) | D10: =Underwriting!B46
A11: Annual Debt Service | B11: =Underwriting!B59 | C11: Total Cash Required | D11: =Underwriting!B57
A13: RETURNS — THE HEADLINE NUMBERS
A14: Going-in Cap Rate | B14: =Underwriting!B62 | C14: DSCR | D14: =Underwriting!B65
A16: Cash-on-Cash (Yr 1) | B16: =Underwriting!B64 | C16: Debt Yield | D16: =Underwriting!B40/Underwriting!B54
A18: Levered IRR | B18: ='Pro Forma & Returns'!B18 | C18: Equity Multiple | D18: ='Pro Forma & Returns'!B19
A20: EXIT ASSUMPTIONS
A21: Hold Period (yrs) | B21: =Underwriting!B49 | C21: Exit Cap Rate | D21: =Underwriting!B50
A22: Annual Rent Growth | B22: =Underwriting!B16 | C22: Annual Expense Growth | D22: =Underwriting!B17
A24: Screening tool only — not investment advice. Verify every figure against the seller's T-12 and rent roll.

Sheet Deal Scorecard
A1: DEAL SCORECARD — LINDAAI FRAMEWORK
A2: Linda's framework. Underwrite to the NORMALIZED NOI (see Normalization tab) before trusting these. GREEN cutoff cells are editable. Part of the LindaAI underwriting framework.
A4: Metric | B4: Deal Value | C4: Linda's rule | D4: Good | E4: OK | F4: (band) | G4: (band) | H4: Rating
A5: GO / NO-GO METRICS (after normalizing the NOI)
A6: DSCR | B6: =Underwriting!B65 | C6: Linda floor: 1.35x to GO | D6: 1.5 | E6: 1.35 | H6: =IF(B6>=D6,"GOOD",IF(B6>=E6,"OK","BAD"))
A7: Cash-on-Cash Return | B7: =Underwriting!B64 | C7: Linda target: 10%+ to GO | D7: 0.1 | E7: 0.08 | H7: =IF(B7>=D7,"GOOD",IF(B7>=E7,"OK","BAD"))
A8: THE 5 QUICK HACKS (screen any listing in ~2 min)
A9: 1% Rule (monthly gross / price) | B9: =(Underwriting!B24/12)/Underwriting!B9 | C9: >=1% likely good | D9: 0.01 | E9: 0.009 | H9: =IF(B9>=D9,"GOOD",IF(B9>=E9,"OK","BAD"))
A10: 10x Rule — GRM (price / annual gross) | B10: =Underwriting!B9/Underwriting!B24 | C10: <10 ideal; >12 pricey | D10: 10 | E10: 12 | H10: =IF(B10<=D10,"GOOD",IF(B10<=E10,"OK","BAD"))
A11: Quick DSCR (NOI / (price x rate)) | B11: =Underwriting!B40/(Underwriting!B9*Underwriting!B45) | C11: >1.5 good; <1.25 risk | D11: 1.5 | E11: 1.25 | H11: =IF(B11>=D11,"GOOD",IF(B11>=E11,"OK","BAD"))
A12: Expense Ratio (OpEx / gross) | B12: =Underwriting!B36 | C12: 35-65% healthy; <30%=fiction | D12: 0.3 | E12: 0.35 | F12: 0.65 | G12: 0.7 | H12: =IF(OR(B12<D12,B12>G12),"BAD",IF(AND(B12>=E12,B12<=F12),"GOOD","OK"))
A13: Leverage spread (cap - interest) | B13: =Underwriting!B62-Underwriting!B45 | C13: cap>rate = positive leverage | D13: 0.02 | E13: 0 | H13: =IF(B13>=D13,"GOOD",IF(B13>=E13,"OK","BAD"))
A14: Expense Ratio is a BAND: below D = BAD (NOI likely inflated / 'fiction') · D-E and F-G = OK · E-F = GOOD (healthy) · above G = BAD. D,E,F,G default to 30/35/65/70%.
A15: VERDICT (Linda's rule: both DSCR and Cash-on-Cash must clear)
A16: DSCR clears floor? | B16: =IF(B6>=E6,"YES","NO")
A17: Cash-on-Cash clears target? | B17: =IF(B7>=D7,"YES","NO")
A19: VERDICT | B19: =IF(AND(B6>=E6,B7>=D7),"GO - both clear",IF(OR(B6>=E6,B7>=D7),"CONDITIONAL - restructure","LIKELY NO-GO"))
A21: Red flags (BAD ratings) | B21: =COUNTIF(H5:H13,"BAD")
A23: CONDITIONAL means restructure to save it (Linda's 3 levers): (1) lower price to your MAO, (2) ask the seller to carry a slice — blended rate drops, DSCR clears, CoC jumps, (3) more down payment. If none work and the seller won't budge, your underwriting just saved you from an expensive mistake.

Sheet Underwriting
A1: RV PARK UNDERWRITING ANALYSIS
A3: Property Name | B3: Enter property name | C3: Yellow cells = your inputs. Everything else calculates.
A4: Location (City, ST) | B4: City, ST
A5: Analysis Date | B5: 2026-06-26
A7: DEAL ASSUMPTIONS
A8: Number of RV Sites (pads) | B8: 50 | C8: total rentable pads
A9: Purchase Price | B9: 1500000
A10: Price per Site | B10: =B9/B8 | C10: purchase price / sites
A11: Avg. Monthly Rent per Site | B11: 450 | C11: blended lot rent / month
A12: Vacancy & Credit Loss % | B12: 0.15 | C12: economic vacancy
A13: Other Income (monthly) | B13: 1500 | C13: store, laundry, propane, fees
A14: Management Fee (% of EGI) | B14: 0.08 | C14: 3rd-party or self-mgmt
A15: Replacement Reserves / site / yr | B15: 100 | C15: capital reserve
A16: Annual Rent Growth % | B16: 0.03 | C16: for multi-year projection
A17: Annual Expense Growth % | B17: 0.025 | C17: for multi-year projection
A18: Use Detailed Income Build? (Y/N) | B18: N | C18: Y = pull GPR from Income Detail tab
A20: INCOME (Year 1 Stabilized Pro Forma)
A21: Gross Potential Rent (GPR) | B21: =IF(B18="Y",'Income Detail'!E30,B8*B11*12) | C21: auto: site mix or sites x rent
A22: Less: Vacancy & Credit Loss | B22: =-B21*B12
A23: Plus: Other Income | B23: =B13*12
A24: Effective Gross Income (EGI) | B24: =B21+B22+B23
A26: OPERATING EXPENSES (Year 1)
A27: Property Taxes | B27: 18000
A28: Insurance | B28: 9000
A29: Utilities (water/sewer/trash/elec) | B29: 36000 | C29: owner-paid portion
A30: Repairs & Maintenance | B30: 15000
A31: Payroll / Onsite Manager | B31: 24000
A32: Marketing, Admin, Office | B32: 8000
A33: Management Fee | B33: =B14*B24 | C33: mgmt % x EGI
A34: Replacement Reserves | B34: =B15*B8
A35: Total Operating Expenses | B35: =SUM(B27:B34)
A36: Operating Expense Ratio | B36: =B35/B24 | C36: OpEx / EGI
A37: Expenses per Site | B37: =B35/B8
A39: NET OPERATING INCOME
A40: Net Operating Income (NOI) | B40: =B24-B35
A41: NOI per Site | B41: =B40/B8
A43: FINANCING & EXIT ASSUMPTIONS
A44: Loan-to-Value (LTV) % | B44: 0.7
A45: Interest Rate % | B45: 0.07 | C45: annual
A46: Amortization (years) | B46: 25
...

Sheet Normalization
A1: NORMALIZE THE NOI — BUILD YOUR OWN NUMBERS
A2: Linda: the T-12 is your starting point but never trusted as-is. Enter the SELLER'S reported figures (yellow); the Normalized column rebuilds the NOI with Linda's 4 adjustments. Part of the LindaAI framework.
A4: LINDA'S NORMALIZATION RULES (editable)
A5: Management Fee (% of EGI) | B5: 0.1 | D5: self-managed owners show little or none
A6: Repairs & Maintenance (% of EGI) | B6: 0.05 | D6: or use the prior-year actual
A7: CapEx / Reserves (% of EGI) | B7: 0.03 | D7: a real cost that's rarely in the P&L
A8: Property Tax bump (%) | B8: 0.2 | D8: taxes reset on sale in disclosure states
A10: INCOME
A11: Effective Gross Income (EGI) | B11: 247500 | C11: =B11 | D11: seller's real top line (Linda: gross income = EGI)
A13: OPERATING EXPENSES
B14: Seller Reported | C14: Normalized | D14: Linda adjustment
A15: Property Taxes | B15: 12000 | C15: =B15*(1+B8) | D15: +20%: resets on sale
A16: Insurance | B16: 8000 | C16: =B16 | D16: pass-through
A17: Utilities (W/S/trash/elec) | B17: 38000 | C17: =B17 | D17: pass-through
A18: Repairs & Maintenance | B18: 4200 | C18: =MAX(B18,B6*B11) | D18: use >=5%% of EGI (deferred maint)
A19: Management Fee | B19: 3500 | C19: =MAX(B19,B5*B11) | D19: use >=10%% of EGI (self-mgmt understates)
A20: CapEx / Reserves | B20: 0 | C20: =MAX(B20,B7*B11) | D20: add >=3%% of EGI (never in P&L)
A21: Payroll / Onsite | B21: 0 | C21: =B21 | D21: pass-through
A22: Marketing / Admin / Other | B22: 6000 | C22: =B22 | D22: pass-through
A23: Total Operating Expenses | B23: =SUM(B15:B22) | C23: =SUM(C15:C22)
A24: Expense Ratio | B24: =B23/B11 | C24: =C23/C11 | D24: Linda: under 30% means something's missing
A26: RESULT
A27: Net Operating Income (NOI) | B27: =B11-B23 | C27: =C11-C23
A28: NOI Haircut ($ cut from seller's NOI) | C28: =B27-C27
A29: NOI Haircut (%) | C29: =(B27-C27)/B27
A30: Valuation Cap Rate (for overpayment calc) | B30: 0.1
A31: OVERPAYMENT RISK (haircut / cap rate) | C31: =(B27-C27)/B30 | D31: Linda: a small NOI cut = a huge price difference
A33: NEXT: carry the NORMALIZED expense figures (column C) into the Underwriting tab so every metric and the Deal Scorecard reflect YOUR numbers, not the seller's.

Sheet Operator & Capital
A1: OPERATOR & VALUE-ADD CAPITAL
A2: A hands-off hold: always pay a professional operator, and size the capital to finish/expand. This tab overlays the Underwriting tab so the returns reflect what you ACTUALLY pocket.
A4: OPERATOR (this is a hands-off hold — always budget one)
A5: NOI before operator | B5: =Underwriting!B40+Underwriting!B33 | C5: =Underwriting NOI + its management line (added back)
A6: Operator Fee ($ / month) | B6: 4000 | C6: flat full-service operator; market mgmt runs ~10-12% of EGI
A7: Operator Fee (annual) | B7: =B6*12
A8: NOI after operator | B8: =B5-B7
A9: Annual Debt Service (from Underwriting) | B9: =Underwriting!B59
A10: Cash Flow after operator (annual) | B10: =B8-B9
A11: Cash Flow after operator (MONTHLY) | B11: =B10/12
A12: Max operator you can afford ($/mo) | B12: =(B5-B9)/12 | C12: break-even ceiling on today's income
A13: DSCR after operator | B13: =IF(B9=0,"n/a",B8/B9)
A15: VALUE-ADD CAPITAL (sources & uses — ON TOP of the down payment)
A16: Finish cabins | B16: 0 | C16: usually highest ROI — near-term income
A17: Finish house / interior | B17: 0 | C17: often marginal — manager housing or defer
A18: Expand pads / development | B18: 0 | C18: phased — needs utilities + permits
A19: Infrastructure / contingency | B19: 0 | C19: septic/sewer eval, reserve
A20: Total Value-Add Capital | B20: =SUM(B16:B19)
A21: Total Cash Invested (all-in) | B21: =Underwriting!B57+B20 | C21: down + closing + day-one capex + value-add
A22: True Cash-on-Cash (today, after operator) | B22: =IF(B21=0,0,B10/B21) | C22: today's cash flow / all-in cash invested
A24: STABILIZED (once the build is done — enter your target NOI)
A25: Stabilized NOI before operator | B25: 0 | C25: cabins leased, rents to market, house online
A26: Stabilized NOI after operator | B26: =IF(B25=0,0,B25-B7)
A27: Stabilized Cash Flow (annual) | B27: =IF(B25=0,0,B26-B9)
A28: Stabilized Cash Flow (MONTHLY) | B28: =IF(B25=0,0,B27/12)
A29: Stabilized True Cash-on-Cash | B29: =IF(OR(B25=0,B21=0),0,B27/B21)
A31: RULE: don't pay the seller for value YOU create with this capital (cabins, house, expansion). Require him to finish income-marketed items before close, or credit you the cost.

Sheet Offer Structures
A1: OFFER STRUCTURES — MAO & SELLER CARRY (LINDA FRAMEWORK)
A2: NOI is held constant (operations don't change with financing). Each column is a price + financing scenario; yellow = editable levers. Verdict uses Linda's rule: DSCR >= target AND Cash-on-Cash >= target.
A4: MAXIMUM ALLOWABLE OFFER — auto-solved (conventional financing)
A5: Target DSCR | B5: 1.35 | C5: Linda floor
A6: Target Cash-on-Cash | B6: 0.1 | C6: Linda target
A7: Bank LTV % (conventional) | B7: 0.7 | C7: loan-to-value for the conventional offer
A8: Bank Interest Rate | B8: 0.07
A9: Amortization (yrs) | B9: 25
A10: NOI (from Underwriting) | B10: =Underwriting!B40
A11: Annual Debt Constant k (per $1 loan) | B11: =PMT(B8/12,B9*12,-1)*12 | C11: annual debt service per $1 borrowed
A12: Max Price @ DSCR target | B12: =B10/(B5*B7*B11) | C12: DSCR-constrained ceiling
A13: Max Price @ Cash-on-Cash target | B13: =(B10-B6*Underwriting!B48)/(B7*B11+B6*(1-B7+Underwriting!B47)) | C13: CoC-constrained ceiling
A14: MAXIMUM ALLOWABLE OFFER (MAO) | B14: =MIN(B12,B13) | C14: highest price where BOTH clear
A16: OFFER COMPARISON (type any price/structure — verdict updates live)
A17: Lever / Metric | B17: Seller Asking | C17: Offer 1: Conventional | D17: Offer 2: Partial Carry | E17: Offer 3: Full Carry
A18: Purchase Price | B18: 1500000 | C18: 1150000 | D18: 1500000 | E18: 1500000 | F18: Offer 1 defaults near the MAO above — type your own to test
A19: Bank Loan % (of price) | B19: 0.7 | C19: 0.7 | D19: 0.65 | E19: 0
A20: Bank Interest Rate | B20: 0.07 | C20: 0.07 | D20: 0.07 | E20: 0.07
A21: Bank Amortization (yrs) | B21: 25 | C21: 25 | D21: 25 | E21: 25
A22: Bank Interest-Only? (Y/N) | B22: N | C22: N | D22: N | E22: N
A23: Seller Carry % (of price) | B23: 0 | C23: 0 | D23: 0.25 | E23: 0.9
A24: Seller Carry Rate | B24: 0 | C24: 0 | D24: 0.05 | E24: 0.06
A25: Seller Carry Amort (yrs) | B25: 25 | C25: 25 | D25: 25 | E25: 25
A26: Seller Carry Interest-Only? (Y/N) | B26: N | C26: N | D26: N | E26: Y
A27: Down Payment % | B27: =1-B19-B23 | C27: =1-C19-C23 | D27: =1-D19-D23 | E27: =1-E19-E23
A28: DEBT STACK
A29: Bank Loan $ | B29: =B18*B19 | C29: =C18*C19 | D29: =D18*D19 | E29: =E18*E19
A30: Bank Annual Debt Service | B30: =IF(B22="Y",B29*B20,PMT(B20/12,B21*12,-B29)*12) | C30: =IF(C22="Y",C29*C20,PMT(C20/12,C21*12,-C29)*12) | D30: =IF(D22="Y",D29*D20,PMT(D20/12,D21*12,-D29)*12) | E30: =IF(E22="Y",E29*E20,PMT(E20/12,E21*12,-E29)*12)
A31: Seller Carry $ | B31: =B18*B23 | C31: =C18*C23 | D31: =D18*D23 | E31: =E18*E23
A32: Seller Carry Annual Debt Service | B32: =IF(B31=0,0,IF(B26="Y",B31*B24,PMT(B24/12,B25*12,-B31)*12)) | C32: =IF(C31=0,0,IF(C26="Y",C31*C24,PMT(C24/12,C25*12,-C31)*12)) | D32: =IF(D31=0,0,IF(D26="Y",D31*D24,PMT(D24/12,D25*12,-D31)*12)) | E32: =IF(E31=0,0,IF(E26="Y",E31*E24,PMT(E24/12,E25*12,-E31)*12))
A33: Total Annual Debt Service | B33: =B30+B32 | C33: =C30+C32 | D33: =D30+D32 | E33: =E30+E32
A34: Blended Rate | B34: =IF((B29+B31)=0,0,(B29*B20+B31*B24)/(B29+B31)) | C34: =IF((C29+C31)=0,0,(C29*C20+C31*C24)/(C29+C31)) | D34: =IF((D29+D31)=0,0,(D29*D20+D31*D24)/(D29+D31)) | E34: =IF((E29+E31)=0,0,(E29*E20+E31*E24)/(E29+E31))
A35: Down Payment $ | B35: =B18*B27 | C35: =C18*C27 | D35: =D18*D27 | E35: =E18*E27
A36: Closing + CapEx | B36: =B18*Underwriting!B47+Underwriting!B48 | C36: =C18*Underwriting!B47+Underwriting!B48 | D36: =D18*Underwriting!B47+Underwriting!B48 | E36: =E18*Underwriting!B47+Underwriting!B48
A37: Total Cash Invested | B37: =B35+B36 | C37: =C35+C36 | D37: =D35+D36 | E37: =E35+E36
A38: KEY METRICS
A39: NOI (constant) | B39: =Underwriting!B40 | C39: =Underwriting!B40 | D39: =Underwriting!B40 | E39: =Underwriting!B40
A40: Cap Rate | B40: =B39/B18 | C40: =C39/C18 | D40: =D39/D18 | E40: =E39/E18
A41: DSCR (total debt) | B41: =IF(B33=0,"n/a",B39/B33) | C41: =IF(C33=0,"n/a",C39/C33) | D41: =IF(D33=0,"n/a",D39/D33) | E41: =IF(E33=0,"n/a",E39/E33)
A42: Net Profit (cash flow) | B42: =B39-B33 | C42: =C39-C33 | D42: =D39-D33 | E42: =E39-E33
...

Sheet Income Detail
A1: INCOME DETAIL — SITE MIX & SEASONALITY
A2: Optional. Build income from your actual site mix, then set 'Use Detailed Income Build?' = Y on the Underwriting tab.
A4: LONG-TERM TENANTS (MONTHLY / ANNUAL LEASES)
A5: Tier | B5: # Sites | C5: Monthly Rate | D5: Occupancy % | E5: Annual Revenue
A6: Monthly tenants | B6: 30 | C6: 450 | D6: 0.95 | E6: =B6*C6*12*D6
A7: Annual / seasonal leases | B7: 8 | C7: 400 | D7: 0.9 | E7: =B7*C7*12*D7
A8: Subtotal — long-term | B8: =SUM(B6:B7) | E8: =SUM(E6:E7)
A10: TRANSIENT / NIGHTLY SITES (SEASONAL)
A11: # Transient sites | B11: 12
A12: Avg nightly rate | B12: 55
A14: Month | B14: Days | C14: Occupancy % | D14: Revenue
A15: Jan | B15: 31 | C15: 0.3 | D15: =$B$11*$B$12*B15*C15
A16: Feb | B16: 28 | C16: 0.3 | D16: =$B$11*$B$12*B16*C16
A17: Mar | B17: 31 | C17: 0.45 | D17: =$B$11*$B$12*B17*C17
A18: Apr | B18: 30 | C18: 0.55 | D18: =$B$11*$B$12*B18*C18
A19: May | B19: 31 | C19: 0.7 | D19: =$B$11*$B$12*B19*C19
A20: Jun | B20: 30 | C20: 0.85 | D20: =$B$11*$B$12*B20*C20
A21: Jul | B21: 31 | C21: 0.95 | D21: =$B$11*$B$12*B21*C21
A22: Aug | B22: 31 | C22: 0.95 | D22: =$B$11*$B$12*B22*C22
A23: Sep | B23: 30 | C23: 0.75 | D23: =$B$11*$B$12*B23*C23
A24: Oct | B24: 31 | C24: 0.55 | D24: =$B$11*$B$12*B24*C24
A25: Nov | B25: 30 | C25: 0.35 | D25: =$B$11*$B$12*B25*C25
A26: Dec | B26: 31 | C26: 0.3 | D26: =$B$11*$B$12*B26*C26
A27: Subtotal — transient | D27: =SUM(D15:D26)
A28: Avg transient occupancy | C28: =SUMPRODUCT(B15:B26,C15:C26)/SUM(B15:B26)
A29: TOTAL POTENTIAL ANNUAL SITE REVENUE
A30: Total Potential Annual Site Revenue | E30: =E8+D27
A31: Total sites in build | E31: =B8+B11
A32: Implied blended monthly rent / site | E32: =E30/E31/12
A33: Note: when Use Detailed Income Build = Y, keep the Underwriting Vacancy % low (credit loss only) — occupancy is already in this build.

Sheet Actuals vs Pro Forma
A1: IN-PLACE ACTUALS vs STABILIZED PRO FORMA
A2: Left column = what the seller is doing TODAY (from their T-12 P&L). Right = your stabilized plan (pulled from Underwriting). The gap is your value-add.
A4: Line Item | B4: In-Place / Actuals | C4: Stabilized Pro Forma | D4: Variance
A5: Gross Potential Rent | B5: 240000 | C5: =Underwriting!B21 | D5: =C5-B5
A6: Vacancy & Credit Loss | B6: -48000 | C6: =Underwriting!B22 | D6: =C6-B6
A7: Other Income | B7: 12000 | C7: =Underwriting!B23 | D7: =C7-B7
A8: Effective Gross Income | B8: =B5+B6+B7 | C8: =Underwriting!B24 | D8: =C8-B8
A9: Property Taxes | B9: 12000 | C9: =Underwriting!B27 | D9: =C9-B9
A10: Insurance | B10: 8000 | C10: =Underwriting!B28 | D10: =C10-B10
A11: Utilities | B11: 38000 | C11: =Underwriting!B29 | D11: =C11-B11
A12: Repairs & Maintenance | B12: 20000 | C12: =Underwriting!B30 | D12: =C12-B12
A13: Payroll / Onsite Mgr | B13: 20000 | C13: =Underwriting!B31 | D13: =C13-B13
A14: Marketing, Admin, Office | B14: 6000 | C14: =Underwriting!B32 | D14: =C14-B14
A15: Management Fee | B15: 0 | C15: =Underwriting!B33 | D15: =C15-B15
A16: Replacement Reserves | B16: 0 | C16: =Underwriting!B34 | D16: =C16-B16
A17: Total Operating Expenses | B17: =SUM(B9:B16) | C17: =Underwriting!B35 | D17: =C17-B17
A18: Net Operating Income | B18: =B8-B17 | C18: =Underwriting!B40 | D18: =C18-B18
A20: Cap Rate at Purchase Price | B20: =B18/Underwriting!B9 | C20: =Underwriting!B62
A22: In-place cap rate = what you're actually buying today. Underwrite to this first, the pro forma second.

Sheet Pro Forma & Returns
A1: 10-YEAR PRO FORMA & RETURNS
A3: Year | B3: 0 | C3: 1 | D3: 2 | E3: 3 | F3: 4 | G3: 5 | H3: 6 | I3: 7 | J3: 8 | K3: 9 | L3: 10
A5: Gross Potential Rent | C5: =Underwriting!B21*(1+Underwriting!B16)^0 | D5: =Underwriting!B21*(1+Underwriting!B16)^1 | E5: =Underwriting!B21*(1+Underwriting!B16)^2 | F5: =Underwriting!B21*(1+Underwriting!B16)^3 | G5: =Underwriting!B21*(1+Underwriting!B16)^4 | H5: =Underwriting!B21*(1+Underwriting!B16)^5 | I5: =Underwriting!B21*(1+Underwriting!B16)^6 | J5: =Underwriting!B21*(1+Underwriting!B16)^7 | K5: =Underwriting!B21*(1+Underwriting!B16)^8 | L5: =Underwriting!B21*(1+Underwriting!B16)^9
A6: Less: Vacancy & Credit Loss | C6: =-C5*Underwriting!B12 | D6: =-D5*Underwriting!B12 | E6: =-E5*Underwriting!B12 | F6: =-F5*Underwriting!B12 | G6: =-G5*Underwriting!B12 | H6: =-H5*Underwriting!B12 | I6: =-I5*Underwriting!B12 | J6: =-J5*Underwriting!B12 | K6: =-K5*Underwriting!B12 | L6: =-L5*Underwriting!B12
A7: Other Income | C7: =Underwriting!B23*(1+Underwriting!B16)^0 | D7: =Underwriting!B23*(1+Underwriting!B16)^1 | E7: =Underwriting!B23*(1+Underwriting!B16)^2 | F7: =Underwriting!B23*(1+Underwriting!B16)^3 | G7: =Underwriting!B23*(1+Underwriting!B16)^4 | H7: =Underwriting!B23*(1+Underwriting!B16)^5 | I7: =Underwriting!B23*(1+Underwriting!B16)^6 | J7: =Underwriting!B23*(1+Underwriting!B16)^7 | K7: =Underwriting!B23*(1+Underwriting!B16)^8 | L7: =Underwriting!B23*(1+Underwriting!B16)^9
A8: Effective Gross Income | C8: =C5+C6+C7 | D8: =D5+D6+D7 | E8: =E5+E6+E7 | F8: =F5+F6+F7 | G8: =G5+G6+G7 | H8: =H5+H6+H7 | I8: =I5+I6+I7 | J8: =J5+J6+J7 | ... L8: =L5+L6+L7
A9: Operating Expenses | C9: =Underwriting!B35*(1+Underwriting!B17)^0 | D9: =Underwriting!B35*(1+Underwriting!B17)^1 | E9: =Underwriting!B35*(1+Underwriting!B17)^2 | F9: =Underwriting!B35*(1+Underwriting!B17)^3 | G9: =Underwriting!B35*(1+Underwriting!B17)^4 | H9: =Underwriting!B35*(1+Underwriting!B17)^5 | I9: =Underwriting!B35*(1+Underwriting!B17)^6 | J9: =Underwriting!B35*(1+Underwriting!B17)^7 | K9: =Underwriting!B35*(1+Underwriting!B17)^8 | L9: =Underwriting!B35*(1+Underwriting!B17)^9
A10: Net Operating Income | C10: =C8-C9 | D10: =D8-D9 | E10: =E8-E9 | F10: =F8-F9 | G10: =G8-G9 | H10: =H8-H9 | I10: =I8-I9 | J10: =J8-J9 | ... L10: =L8-L9
A11: Annual Debt Service | C11: =IF(1<=Underwriting!B49,Underwriting!B59,0) | D11: =IF(2<=Underwriting!B49,Underwriting!B59,0) | E11: =IF(3<=Underwriting!B49,Underwriting!B59,0) | F11: =IF(4<=Underwriting!B49,Underwriting!B59,0) | G11: =IF(5<=Underwriting!B49,Underwriting!B59,0) | H11: =IF(6<=Underwriting!B49,Underwriting!B59,0) | I11: =IF(7<=Underwriting!B49,Underwriting!B59,0) | J11: =IF(8<=Underwriting!B49,Underwriting!B59,0) | K11: =IF(9<=Underwriting!B49,Underwriting!B59,0) | L11: =IF(10<=Underwriting!B49,Underwriting!B59,0)
A12: Loan Balance (end of yr) | B12: =Underwriting!B54 | C12: =Underwriting!B54*(1+(Underwriting!B45/12))^(MIN(1,Underwriting!B46)*12)-Underwriting!B58*(((1+(Underwriting!B45/12))^(MIN(1,Underwriting!B46)*12)-1)/(Underwriting!B45/12)) | D12: =Underwriting!B54*(1+(Underwriting!B45/12))^(MIN(2,Underwriting!B46)*12)-Underwriting!B58*(((1+(Underwriting!B45/12))^(MIN(2,Underwriting!B46)*12)-1)/(Underwriting!B45/12)) | E12: =Underwriting!B54*(1+(Underwriting!B45/12))^(MIN(3,Underwriting!B46)*12)-Underwriting!B58*(((1+(Underwriting!B45/12))^(MIN(3,Underwriting!B46)*12)-1)/(Underwriting!B45/12)) | F12: =Underwriting!B54*(1+(Underwriting!B45/12))^(MIN(4,Underwriting!B46)*12)-Underwriting!B58*(((1+(Underwriting!B45/12))^(MIN(4,Underwriting!B46)*12)-1)/(Underwriting!B45/12)) | G12: =Underwriting!B54*(1+(Underwriting!B45/12))^(MIN(5,Underwriting!B46)*12)-Underwriting!B58*(((1+(Underwriting!B45/12))^(MIN(5,Underwriting!B46)*12)-1)/(Underwriting!B45/12)) | H12: =Underwriting!B54*(1+(Underwriting!B45/12))^(MIN(6,Underwriting!B46)*12)-Underwriting!B58*(((1+(Underwriting!B45/12))^(MIN(6,Underwriting!B46)*12)-1)/(Underwriting!B45/12)) | I12: =Underwriting!B54*(1+(Underwriting!B45/12))^(MIN(7,Underwriting!B46)*12)-Underwriting!B58*(((1+(Underwriting!B45/12))^(MIN(7,Underwriting!B46)*12)-1)/(Underwriting!B45/12)) | J12: =Underwriting!B54*(1+(Underwriting!B45/12))^(MIN(8,Underwriting!B46)*12)-Underwriting!B58*(((1+(Underwriting!B45/12))^(MIN(8,Underwriting!B46)*12)-1)/(Underwriting!B45/12)) | K12: =Underwriting!B54*(1+(Underwriting!B45/12))^(MIN(9,Underwriting!B46)*12)-Underwriting!B58*(((1+(Underwriting!B45/12))^(MIN(9,Underwriting!B46)*12)-1)/(Underwriting!B45/12)) | L12: =Underwriting!B54*(1+(Underwriting!B45/12))^(MIN(10,Underwriting!B46)*12)-Underwriting!B58*(((1+(Underwriting!B45/12))^(MIN(10,Underwriting!B46)*12)-1)/(Underwriting!B45/12))
A13: Operating Cash Flow | C13: =IF(1<=Underwriting!B49,C10-C11,0) | D13: =IF(2<=Underwriting!B49,D10-D11,0) | E13: =IF(3<=Underwriting!B49,E10-E11,0) | F13: =IF(4<=Underwriting!B49,F10-F11,0) | G13: =IF(5<=Underwriting!B49,G10-G11,0) | H13: =IF(6<=Underwriting!B49,H10-H11,0) | I13: =IF(7<=Underwriting!B49,I10-I11,0) | J13: =IF(8<=Underwriting!B49,J10-J11,0) | K13: =IF(9<=Underwriting!B49,K10-K11,0) | L13: =IF(10<=Underwriting!B49,L10-L11,0)
A14: Net Sale Proceeds (reversion) | C14: =IF(1=Underwriting!B49,((C10*(1+Underwriting!B16))/Underwriting!B50)*(1-Underwriting!B51)-C12,0) | D14: =IF(2=Underwriting!B49,((D10*(1+Underwriting!B16))/Underwriting!B50)*(1-Underwriting!B51)-D12,0) | E14: =IF(3=Underwriting!B49,((E10*(1+Underwriting!B16))/Underwriting!B50)*(1-Underwriting!B51)-E12,0) | F14: =IF(4=Underwriting!B49,((F10*(1+Underwriting!B16))/Underwriting!B50)*(1-Underwriting!B51)-F12,0) | G14: =IF(5=Underwriting!B49,((G10*(1+Underwriting!B16))/Underwriting!B50)*(1-Underwriting!B51)-G12,0) | H14: =IF(6=Underwriting!B49,((H10*(1+Underwriting!B16))/Underwriting!B50)*(1-Underwriting!B51)-H12,0) | I14: =IF(7=Underwriting!B49,((I10*(1+Underwriting!B16))/Underwriting!B50)*(1-Underwriting!B51)-I12,0) | J14: =IF(8=Underwriting!B49,((J10*(1+Underwriting!B16))/Underwriting!B50)*(1-Underwriting!B51)-J12,0) | K14: =IF(9=Underwriting!B49,((K10*(1+Underwriting!B16))/Underwriting!B50)*(1-Underwriting!B51)-K12,0) | L14: =IF(10=Underwriting!B49,((L10*(1+Underwriting!B16))/Underwriting!B50)*(1-Underwriting!B51)-L12,0)
A15: Total Cash Flow (for IRR) | B15: =-Underwriting!B57 | C15: =C13+C14 | D15: =D13+D14 | E15: =E13+E14 | F15: =F13+F14 | G15: =G13+G14 | H15: =H13+H14 | I15: =I13+I14 | J15: =J13+J14 | ... L15: =L13+L14
A17: RETURN SUMMARY (over hold period)
A18: Levered IRR | B18: =IRR(B15:L15) | C18: internal rate of return on equity
A19: Equity Multiple | B19: =(SUM(C13:L13)+SUM(C14:L14))/-B15 | C19: total cash returned / equity
A20: Avg. Cash-on-Cash | B20: =AVERAGEIF(C11:L11,">0",C13:L13)/Underwriting!B57 | C20: avg operating CF / equity during hold
A21: Year-1 Cash-on-Cash | B21: =Underwriting!B64
A22: Going-in Cap Rate | B22: =Underwriting!B62
A23: Total Profit | B23: =SUM(C13:L13)+SUM(C14:L14)+B15 | C23: all cash flows incl. equity out

Sheet Sensitivity
A1: SENSITIVITY TABLES
A2: Rows = purchase price scenarios. Columns = interest rate. Cells recompute live from Underwriting inputs.
A4: CASH-ON-CASH RETURN — Price x Interest Rate
A5: Price \ Rate | B5: =Underwriting!B45+-0.01 | C5: =Underwriting!B45+-0.005 | D5: =Underwriting!B45+0 | E5: =Underwriting!B45+0.005 | F5: =Underwriting!B45+0.01
A6: =Underwriting!B9*0.9 | B6: =(Underwriting!B40-((($A6*Underwriting!B44)*(B$5/12)/(1-(1+B$5/12)^(-Underwriting!B46*12)))*12))/($A6*(1-Underwriting!B44)+$A6*Underwriting!B47+Underwriting!B48) | C6: =(Underwriting!B40-((($A6*Underwriting!B44)*(C$5/12)/(1-(1+C$5/12)^(-Underwriting!B46*12)))*12))/($A6*(1-Underwriting!B44)+$A6*Underwriting!B47+Underwriting!B48) | D6: =(Underwriting!B40-((($A6*Underwriting!B44)*(D$5/12)/(1-(1+D$5/12)^(-Underwriting!B46*12)))*12))/($A6*(1-Underwriting!B44)+$A6*Underwriting!B47+Underwriting!B48) | E6: =(Underwriting!B40-((($A6*Underwriting!B44)*(E$5/12)/(1-(1+E$5/12)^(-Underwriting!B46*12)))*12))/($A6*(1-Underwriting!B44)+$A6*Underwriting!B47+Underwriting!B48) | F6: =(Underwriting!B40-((($A6*Underwriting!B44)*(F$5/12)/(1-(1+F$5/12)^(-Underwriting!B46*12)))*12))/($A6*(1-Underwriting!B44)+$A6*Underwriting!B47+Underwriting!B48)
A7: =Underwriting!B9*0.95 | B7: =(Underwriting!B40-((($A7*Underwriting!B44)*(B$5/12)/(1-(1+B$5/12)^(-Underwriting!B46*12)))*12))/($A7*(1-Underwriting!B44)+$A7*Underwriting!B47+Underwriting!B48) | C7: =(Underwriting!B40-((($A7*Underwriting!B44)*(C$5/12)/(1-(1+C$5/12)^(-Underwriting!B46*12)))*12))/($A7*(1-Underwriting!B44)+$A7*Underwriting!B47+Underwriting!B48) | D7: =(Underwriting!B40-((($A7*Underwriting!B44)*(D$5/12)/(1-(1+D$5/12)^(-Underwriting!B46*12)))*12))/($A7*(1-Underwriting!B44)+$A7*Underwriting!B47+Underwriting!B48) | E7: =(Underwriting!B40-((($A7*Underwriting!B44)*(E$5/12)/(1-(1+E$5/12)^(-Underwriting!B46*12)))*12))/($A7*(1-Underwriting!B44)+$A7*Underwriting!B47+Underwriting!B48) | F7: =(Underwriting!B40-((($A7*Underwriting!B44)*(F$5/12)/(1-(1+F$5/12)^(-Underwriting!B46*12)))*12))/($A7*(1-Underwriting!B44)+$A7*Underwriting!B47+Underwriting!B48)
A8: =Underwriting!B9*1.0 | B8: =(Underwriting!B40-((($A8*Underwriting!B44)*(B$5/12)/(1-(1+B$5/12)^(-Underwriting!B46*12)))*12))/($A8*(1-Underwriting!B44)+$A8*Underwriting!B47+Underwriting!B48) | C8: =(Underwriting!B40-((($A8*Underwriting!B44)*(C$5/12)/(1-(1+C$5/12)^(-Underwriting!B46*12)))*12))/($A8*(1-Underwriting!B44)+$A8*Underwriting!B47+Underwriting!B48) | D8: =(Underwriting!B40-((($A8*Underwriting!B44)*(D$5/12)/(1-(1+D$5/12)^(-Underwriting!B46*12)))*12))/($A8*(1-Underwriting!B44)+$A8*Underwriting!B47+Underwriting!B48) | E8: =(Underwriting!B40-((($A8*Underwriting!B44)*(E$5/12)/(1-(1+E$5/12)^(-Underwriting!B46*12)))*12))/($A8*(1-Underwriting!B44)+$A8*Underwriting!B47+Underwriting!B48) | F8: =(Underwriting!B40-((($A8*Underwriting!B44)*(F$5/12)/(1-(1+F$5/12)^(-Underwriting!B46*12)))*12))/($A8*(1-Underwriting!B44)+$A8*Underwriting!B47+Underwriting!B48)
A9: =Underwriting!B9*1.05 | B9: =(Underwriting!B40-((($A9*Underwriting!B44)*(B$5/12)/(1-(1+B$5/12)^(-Underwriting!B46*12)))*12))/($A9*(1-Underwriting!B44)+$A9*Underwriting!B47+Underwriting!B48) | C9: =(Underwriting!B40-((($A9*Underwriting!B44)*(C$5/12)/(1-(1+C$5/12)^(-Underwriting!B46*12)))*12))/($A9*(1-Underwriting!B44)+$A9*Underwriting!B47+Underwriting!B48) | D9: =(Underwriting!B40-((($A9*Underwriting!B44)*(D$5/12)/(1-(1+D$5/12)^(-Underwriting!B46*12)))*12))/($A9*(1-Underwriting!B44)+$A9*Underwriting!B47+Underwriting!B48) | E9: =(Underwriting!B40-((($A9*Underwriting!B44)*(E$5/12)/(1-(1+E$5/12)^(-Underwriting!B46*12)))*12))/($A9*(1-Underwriting!B44)+$A9*Underwriting!B47+Underwriting!B48) | F9: =(Underwriting!B40-((($A9*Underwriting!B44)*(F$5/12)/(1-(1+F$5/12)^(-Underwriting!B46*12)))*12))/($A9*(1-Underwriting!B44)+$A9*Underwriting!B47+Underwriting!B48)
A10: =Underwriting!B9*1.1 | B10: =(Underwriting!B40-((($A10*Underwriting!B44)*(B$5/12)/(1-(1+B$5/12)^(-Underwriting!B46*12)))*12))/($A10*(1-Underwriting!B44)+$A10*Underwriting!B47+Underwriting!B48) | C10: =(Underwriting!B40-((($A10*Underwriting!B44)*(C$5/12)/(1-(1+C$5/12)^(-Underwriting!B46*12)))*12))/($A10*(1-Underwriting!B44)+$A10*Underwriting!B47+Underwriting!B48) | D10: =(Underwriting!B40-((($A10*Underwriting!B44)*(D$5/12)/(1-(1+D$5/12)^(-Underwriting!B46*12)))*12))/($A10*(1-Underwriting!B44)+$A10*Underwriting!B47+Underwriting!B48) | E10: =(Underwriting!B40-((($A10*Underwriting!B44)*(E$5/12)/(1-(1+E$5/12)^(-Underwriting!B46*12)))*12))/($A10*(1-Underwriting!B44)+$A10*Underwriting!B47+Underwriting!B48) | F10: =(Underwriting!B40-((($A10*Underwriting!B44)*(F$5/12)/(1-(1+F$5/12)^(-Underwriting!B46*12)))*12))/($A10*(1-Underwriting!B44)+$A10*Underwriting!B47+Underwriting!B48)
A13: DEBT SERVICE COVERAGE (DSCR) — Price x Interest Rate
A14: Price \ Rate | B14: =Underwriting!B45+-0.01 | C14: =Underwriting!B45+-0.005 | D14: =Underwriting!B45+0 | E14: =Underwriting!B45+0.005 | F14: =Underwriting!B45+0.01
A15: =Underwriting!B9*0.9 | B15: =Underwriting!B40/((($A15*Underwriting!B44)*(B$14/12)/(1-(1+B$14/12)^(-Underwriting!B46*12)))*12) | C15: =Underwriting!B40/((($A15*Underwriting!B44)*(C$14/12)/(1-(1+C$14/12)^(-Underwriting!B46*12)))*12) | D15: =Underwriting!B40/((($A15*Underwriting!B44)*(D$14/12)/(1-(1+D$14/12)^(-Underwriting!B46*12)))*12) | E15: =Underwriting!B40/((($A15*Underwriting!B44)*(E$14/12)/(1-(1+E$14/12)^(-Underwriting!B46*12)))*12) | F15: =Underwriting!B40/((($A15*Underwriting!B44)*(F$14/12)/(1-(1+F$14/12)^(-Underwriting!B46*12)))*12)
A16: =Underwriting!B9*0.95 | B16: =Underwriting!B40/((($A16*Underwriting!B44)*(B$14/12)/(1-(1+B$14/12)^(-Underwriting!B46*12)))*12) | C16: =Underwriting!B40/((($A16*Underwriting!B44)*(C$14/12)/(1-(1+C$14/12)^(-Underwriting!B46*12)))*12) | D16: =Underwriting!B40/((($A16*Underwriting!B44)*(D$14/12)/(1-(1+D$14/12)^(-Underwriting!B46*12)))*12) | E16: =Underwriting!B40/((($A16*Underwriting!B44)*(E$14/12)/(1-(1+E$14/12)^(-Underwriting!B46*12)))*12) | F16: =Underwriting!B40/((($A16*Underwriting!B44)*(F$14/12)/(1-(1+F$14/12)^(-Underwriting!B46*12)))*12)
A17: =Underwriting!B9*1.0 | B17: =Underwriting!B40/((($A17*Underwriting!B44)*(B$14/12)/(1-(1+B$14/12)^(-Underwriting!B46*12)))*12) | C17: =Underwriting!B40/((($A17*Underwriting!B44)*(C$14/12)/(1-(1+C$14/12)^(-Underwriting!B46*12)))*12) | D17: =Underwriting!B40/((($A17*Underwriting!B44)*(D$14/12)/(1-(1+D$14/12)^(-Underwriting!B46*12)))*12) | E17: =Underwriting!B40/((($A17*Underwriting!B44)*(E$14/12)/(1-(1+E$14/12)^(-Underwriting!B46*12)))*12) | F17: =Underwriting!B40/((($A17*Underwriting!B44)*(F$14/12)/(1-(1+F$14/12)^(-Underwriting!B46*12)))*12)
A18: =Underwriting!B9*1.05 | B18: =Underwriting!B40/((($A18*Underwriting!B44)*(B$14/12)/(1-(1+B$14/12)^(-Underwriting!B46*12)))*12) | C18: =Underwriting!B40/((($A18*Underwriting!B44)*(C$14/12)/(1-(1+C$14/12)^(-Underwriting!B46*12)))*12) | D18: =Underwriting!B40/((($A18*Underwriting!B44)*(D$14/12)/(1-(1+D$14/12)^(-Underwriting!B46*12)))*12) | E18: =Underwriting!B40/((($A18*Underwriting!B44)*(E$14/12)/(1-(1+E$14/12)^(-Underwriting!B46*12)))*12) | F18: =Underwriting!B40/((($A18*Underwriting!B44)*(F$14/12)/(1-(1+F$14/12)^(-Underwriting!B46*12)))*12)
A19: =Underwriting!B9*1.1 | B19: =Underwriting!B40/((($A19*Underwriting!B44)*(B$14/12)/(1-(1+B$14/12)^(-Underwriting!B46*12)))*12) | C19: =Underwriting!B40/((($A19*Underwriting!B44)*(C$14/12)/(1-(1+C$14/12)^(-Underwriting!B46*12)))*12) | D19: =Underwriting!B40/((($A19*Underwriting!B44)*(D$14/12)/(1-(1+D$14/12)^(-Underwriting!B46*12)))*12) | E19: =Underwriting!B40/((($A19*Underwriting!B44)*(E$14/12)/(1-(1+E$14/12)^(-Underwriting!B46*12)))*12) | F19: =Underwriting!B40/((($A19*Underwriting!B44)*(F$14/12)/(1-(1+F$14/12)^(-Underwriting!B46*12)))*12)
A21: NOTE: the two tables above hold NOI constant to isolate price & financing risk.
A23: CASH-ON-CASH RETURN — Monthly Rent x Vacancy
A24: Rent \ Vacancy | B24: 0.05 | C24: 0.1 | D24: 0.15 | E24: 0.2 | F24: 0.25
A25: =Underwriting!B11+-100 | B25: =(((Underwriting!B8*$A25*12*(1-B$24)+Underwriting!B23)-((Underwriting!B35-Underwriting!B33)+Underwriting!B14*(Underwriting!B8*$A25*12*(1-B$24)+Underwriting!B23)))-Underwriting!B59)/Underwriting!B57 | C25: =(((Underwriting!B8*$A25*12*(1-C$24)+Underwriting!B23)-((Underwriting!B35-Underwriting!B33)+Underwriting!B14*(Underwriting!B8*$A25*12*(1-C$24)+Underwriting!B23)))-Underwriting!B59)/Underwriting!B57 | D25: =(((Underwriting!B8*$A25*12*(1-D$24)+Underwriting!B23)-((Underwriting!B35-Underwriting!B33)+Underwriting!B14*(Underwriting!B8*$A25*12*(1-D$24)+Underwriting!B23)))-Underwriting!B59)/Underwriting!B57 | E25: =(((Underwriting!B8*$A25*12*(1-E$24)+Underwriting!B23)-((Underwriting!B35-Underwriting!B33)+Underwriting!B14*(Underwriting!B8*$A25*12*(1-E$24)+Underwriting!B23)))-Underwriting!B59)/Underwriting!B57 | F25: =(((Underwriting!B8*$A25*12*(1-F$24)+Underwriting!B23)-((Underwriting!B35-Underwriting!B33)+Underwriting!B14*(Underwriting!B8*$A25*12*(1-F$24)+Underwriting!B23)))-Underwriting!B59)/Underwriting!B57
A26: =Underwriting!B11+-50 | B26: =(((Underwriting!B8*$A26*12*(1-B$24)+Underwriting!B23)-((Underwriting!B35-Underwriting!B33)+Underwriting!B14*(Underwriting!B8*$A26*12*(1-B$24)+Underwriting!B23)))-Underwriting!B59)/Underwriting!B57 | C26: =(((Underwriting!B8*$A26*12*(1-C$24)+Underwriting!B23)-((Underwriting!B35-Underwriting!B33)+Underwriting!B14*(Underwriting!B8*$A26*12*(1-C$24)+Underwriting!B23)))-Underwriting!B59)/Underwriting!B57 | D26: =(((Underwriting!B8*$A26*12*(1-D$24)+Underwriting!B23)-((Underwriting!B35-Underwriting!B33)+Underwriting!B14*(Underwriting!B8*$A26*12*(1-D$24)+Underwriting!B23)))-Underwriting!B59)/Underwriting!B57 | E26: =(((Underwriting!B8*$A26*12*(1-E$24)+Underwriting!B23)-((Underwriting!B35-Underwriting!B33)+Underwriting!B14*(Underwriting!B8*$A26*12*(1-E$24)+Underwriting!B23)))-Underwriting!B59)/Underwriting!B57 | F26: =(((Underwriting!B8*$A26*12*(1-F$24)+Underwriting!B23)-((Underwriting!B35-Underwriting!B33)+Underwriting!B14*(Underwriting!B8*$A26*12*(1-F$24)+Underwriting!B23)))-Underwriting!B59)/Underwriting!B57
A27: =Underwriting!B11+0 | B27: =(((Underwriting!B8*$A27*12*(1-B$24)+Underwriting!B23)-((Underwriting!B35-Underwriting!B33)+Underwriting!B14*(Underwriting!B8*$A27*12*(1-B$24)+Underwriting!B23)))-Underwriting!B59)/Underwriting!B57 | C27: =(((Underwriting!B8*$A27*12*(1-C$24)+Underwriting!B23)-((Underwriting!B35-Underwriting!B33)+Underwriting!B14*(Underwriting!B8*$A27*12*(1-C$24)+Underwriting!B23)))-Underwriting!B59)/Underwriting!B57 | D27: =(((Underwriting!B8*$A27*12*(1-D$24)+Underwriting!B23)-((Underwriting!B35-Underwriting!B33)+Underwriting!B14*(Underwriting!B8*$A27*12*(1-D$24)+Underwriting!B23)))-Underwriting!B59)/Underwriting!B57 | E27: =(((Underwriting!B8*$A27*12*(1-E$24)+Underwriting!B23)-((Underwriting!B35-Underwriting!B33)+Underwriting!B14*(Underwriting!B8*$A27*12*(1-E$24)+Underwriting!B23)))-Underwriting!B59)/Underwriting!B57 | F27: =(((Underwriting!B8*$A27*12*(1-F$24)+Underwriting!B23)-((Underwriting!B35-Underwriting!B33)+Underwriting!B14*(Underwriting!B8*$A27*12*(1-F$24)+Underwriting!B23)))-Underwriting!B59)/Underwriting!B57
A28: =Underwriting!B11+50 | B28: =(((Underwriting!B8*$A28*12*(1-B$24)+Underwriting!B23)-((Underwriting!B35-Underwriting!B33)+Underwriting!B14*(Underwriting!B8*$A28*12*(1-B$24)+Underwriting!B23)))-Underwriting!B59)/Underwriting!B57 | C28: =(((Underwriting!B8*$A28*12*(1-C$24)+Underwriting!B23)-((Underwriting!B35-Underwriting!B33)+Underwriting!B14*(Underwriting!B8*$A28*12*(1-C$24)+Underwriting!B23)))-Underwriting!B59)/Underwriting!B57 | D28: =(((Underwriting!B8*$A28*12*(1-D$24)+Underwriting!B23)-((Underwriting!B35-Underwriting!B33)+Underwriting!B14*(Underwriting!B8*$A28*12*(1-D$24)+Underwriting!B23)))-Underwriting!B59)/Underwriting!B57 | E28: =(((Underwriting!B8*$A28*12*(1-E$24)+Underwriting!B23)-((Underwriting!B35-Underwriting!B33)+Underwriting!B14*(Underwriting!B8*$A28*12*(1-E$24)+Underwriting!B23)))-Underwriting!B59)/Underwriting!B57 | F28: =(((Underwriting!B8*$A28*12*(1-F$24)+Underwriting!B23)-((Underwriting!B35-Underwriting!B33)+Underwriting!B14*(Underwriting!B8*$A28*12*(1-F$24)+Underwriting!B23)))-Underwriting!B59)/Underwriting!B57
A29: =Underwriting!B11+100 | B29: =(((Underwriting!B8*$A29*12*(1-B$24)+Underwriting!B23)-((Underwriting!B35-Underwriting!B33)+Underwriting!B14*(Underwriting!B8*$A29*12*(1-B$24)+Underwriting!B23)))-Underwriting!B59)/Underwriting!B57 | C29: =(((Underwriting!B8*$A29*12*(1-C$24)+Underwriting!B23)-((Underwriting!B35-Underwriting!B33)+Underwriting!B14*(Underwriting!B8*$A29*12*(1-C$24)+Underwriting!B23)))-Underwriting!B59)/Underwriting!B57 | D29: =(((Underwriting!B8*$A29*12*(1-D$24)+Underwriting!B23)-((Underwriting!B35-Underwriting!B33)+Underwriting!B14*(Underwriting!B8*$A29*12*(1-D$24)+Underwriting!B23)))-Underwriting!B59)/Underwriting!B57 | E29: =(((Underwriting!B8*$A29*12*(1-E$24)+Underwriting!B23)-((Underwriting!B35-Underwriting!B33)+Underwriting!B14*(Underwriting!B8*$A29*12*(1-E$24)+Underwriting!B23)))-Underwriting!B59)/Underwriting!B57 | F29: =(((Underwriting!B8*$A29*12*(1-F$24)+Underwriting!B23)-((Underwriting!B35-Underwriting!B33)+Underwriting!B14*(Underwriting!B8*$A29*12*(1-F$24)+Underwriting!B23)))-Underwriting!B59)/Underwriting!B57
A31: NOTE: this table recomputes NOI (management fee scales with EGI). Uses sites x rent income, not the Income Detail build.

Sheet Loan Sizing
A1: LOAN SIZING — MAX PRICE AT TARGET DSCR
A2: Works backward from how much debt the NOI supports. NOI is held at the Underwriting Year-1 figure; rate, amortization and LTV come from the Underwriting tab.
A4: TARGETS (your / the lender's limits)
A5: Target DSCR | B5: 1.25 | C5: minimum coverage lender requires
A6: Target Debt Yield | B6: 0.1 | C6: NOI / loan floor (often 9-10%)
A7: Max LTV % | B7: 0.75 | C7: lender's loan-to-value cap
A9: LOAN INPUTS (from Underwriting)
A10: Year-1 NOI | B10: =Underwriting!B40
A11: Interest Rate | B11: =Underwriting!B45
A12: Amortization (yrs) | B12: =Underwriting!B46
A13: Annual Debt Constant (per $1 loan) | B13: =PMT(B11/12,B12*12,-1)*12 | C13: annual debt service per $1 borrowed
A15: MAXIMUM SUPPORTABLE LOAN
A16: Max Annual Debt Service (DSCR) | B16: =B10/B5 | C16: NOI / target DSCR
A17: Max Loan — DSCR constrained | B17: =B16/B13
A18: Max Loan — Debt-Yield constrained | B18: =B10/B6
A19: Binding Max Loan | B19: =MIN(B17,B18) | C19: the lesser of the two
A21: MAXIMUM PURCHASE PRICE
A22: Max Price — DSCR/Debt-Yield (at Max LTV) | B22: =B19/B7 | C22: price the debt supports at your LTV
A23: Current Purchase Price | B23: =Underwriting!B9
A24: Price Headroom ($) | B24: =B22-B23 | C24: positive = room to pay more; negative = overpaying
A25: Price Headroom (%) | B25: =B24/B23
A26: DSCR at Current Price | B26: =Underwriting!B65 | C26: for reference (target above)
A27: Required Equity at Max Price | B27: =B22*(1-B7) | C27: down payment if you buy at the max
A29: READ: if Headroom is negative, the price is higher than the income can safely finance at your target DSCR — you'd need more equity, a lower rate, or a price cut.
